e5_2
Models outputs /mnt/lustre/projects/vs25/Tin
0.001
5
16
False
skip_training False
outputs/real_alphabets_F256_pow2.csv
Estimated number of samples: 12800
Estimated input data size: 5.12 MB
Estimated label size: 5.12 MB
Estimated Total Dataset size: 10.24 MB
Input data shape: (678150, 316) (316,)
Label data shape: (678150, 316) (316,)
Input data shape: torch.Size([16, 1, 316])
Labels shape: torch.Size([16, 316])
Let's use 7 GPUs!
Traceback (most recent call last):
  File "parallel.py", line 748, in <module>
    a = model(data.float().to(device))
  File "/usr/local/pytorch/1.5-cuda10/pytorch-1.5-cuda10-venv/lib/python3.7/site-packages/torch/nn/modules/module.py", line 550, in __call__
    result = self.forward(*input, **kwargs)
  File "/usr/local/pytorch/1.5-cuda10/pytorch-1.5-cuda10-venv/lib/python3.7/site-packages/torch/nn/parallel/data_parallel.py", line 155, in forward
    outputs = self.parallel_apply(replicas, inputs, kwargs)
  File "/usr/local/pytorch/1.5-cuda10/pytorch-1.5-cuda10-venv/lib/python3.7/site-packages/torch/nn/parallel/data_parallel.py", line 165, in parallel_apply
    return parallel_apply(replicas, inputs, kwargs, self.device_ids[:len(replicas)])
  File "/usr/local/pytorch/1.5-cuda10/pytorch-1.5-cuda10-venv/lib/python3.7/site-packages/torch/nn/parallel/parallel_apply.py", line 85, in parallel_apply
    output.reraise()
  File "/usr/local/pytorch/1.5-cuda10/pytorch-1.5-cuda10-venv/lib/python3.7/site-packages/torch/_utils.py", line 395, in reraise
    raise self.exc_type(msg)
AttributeError: Caught AttributeError in replica 0 on device 0.
Original Traceback (most recent call last):
  File "/usr/local/pytorch/1.5-cuda10/pytorch-1.5-cuda10-venv/lib/python3.7/site-packages/torch/nn/parallel/parallel_apply.py", line 60, in _worker
    output = module(*input, **kwargs)
  File "/usr/local/pytorch/1.5-cuda10/pytorch-1.5-cuda10-venv/lib/python3.7/site-packages/torch/nn/modules/module.py", line 550, in __call__
    result = self.forward(*input, **kwargs)
  File "parallel.py", line 709, in forward
    self.lstm.flatten_parameters()
  File "/usr/local/pytorch/1.5-cuda10/pytorch-1.5-cuda10-venv/lib/python3.7/site-packages/torch/nn/modules/module.py", line 594, in __getattr__
    type(self).__name__, name))
AttributeError: 'CNN_LSTM' object has no attribute 'lstm'

srun: error: ge01: task 0: Exited with exit code 1
